<?xml version="1.0"?>
<robot name="arm_2" xmlns:xacro="http://ros.org/wiki/xacro">

  <link
    name="mani2_base">
    <inertial>
      <origin
        xyz="-3.1029E-18 3.9676E-18 0.006"
        rpy="0 0 0" />
      <mass
        value="0.43725" />
      <inertia
        ixx="0.0015698"
        ixy="1.096E-20"
        ixz="1.1641E-20"
        iyy="0.0015694"
        iyz="-1.1277E-20"
        izz="0.0031287" />
    </inertial>
    <visual>
      <origin
        xyz="0 0 0"
        rpy="0 0 0" />
      <geometry>
        <mesh
          filename="package://dualarm_config/meshes/mani2_base.STL" />
      </geometry>
      <material
        name="">
        <color
          rgba="0.79216 0.81961 0.93333 1" />
      </material>
    </visual>
    <collision>
      <origin
        xyz="0 0 0"
        rpy="0 0 0" />
      <geometry>
        <mesh
          filename="package://dualarm_config/meshes/mani2_base.STL" />
      </geometry>
    </collision>
  </link>
  <link
    name="mani2_link1">
    <inertial>
      <origin
        xyz="0.00025963 -4.4216E-06 0.06121"
        rpy="0 0 0" />
      <mass
        value="0.67076" />
      <inertia
        ixx="0.00095513"
        ixy="-1.4502E-08"
        ixz="-1.0271E-06"
        iyy="0.00094832"
        iyz="-1.8227E-09"
        izz="0.0012889" />
    </inertial>
    <visual>
      <origin
        xyz="0 0 0"
        rpy="0 0 0" />
      <geometry>
        <mesh
          filename="package://dualarm_config/meshes/mani2_link1.STL" />
      </geometry>
      <material
        name="">
        <color
          rgba="0.79216 0.81961 0.93333 1" />
      </material>
    </visual>
    <collision>
      <origin
        xyz="0 0 0"
        rpy="0 0 0" />
      <geometry>
        <mesh
          filename="package://dualarm_config/meshes/mani2_link1.STL" />
      </geometry>
    </collision>
  </link>
  <joint
    name="mani2_fixed"
    type="fixed">
    <origin
      xyz="0 0 0.012"
      rpy="0 0 1.5708" />
    <parent
      link="mani2_base" />
    <child
      link="mani2_link1" />
    <axis
      xyz="0 0 0" />
  </joint>
  <link
    name="mani2_link2">
    <inertial>
      <origin
        xyz="6.849E-05 -0.015121 0.063905"
        rpy="0 0 0" />
      <mass
        value="0.63538" />
      <inertia
        ixx="0.00072901"
        ixy="-3.9612E-07"
        ixz="1.1922E-06"
        iyy="0.0010627"
        iyz="2.6423E-06"
        izz="0.00069297" />
    </inertial>
    <visual>
      <origin
        xyz="0 0 0"
        rpy="0 0 0" />
      <geometry>
        <mesh
          filename="package://dualarm_config/meshes/mani2_link2.STL" />
      </geometry>
      <material
        name="">
        <color
          rgba="0.79216 0.81961 0.93333 1" />
      </material>
    </visual>
    <collision>
      <origin
        xyz="0 0 0"
        rpy="0 0 0" />
      <geometry>
        <mesh
          filename="package://dualarm_config/meshes/mani2_link2.STL" />
      </geometry>
    </collision>
  </link>
  <joint
    name="mani2_joint1"
    type="revolute">
    <origin
      xyz="0 0 0.125"
      rpy="0 0 1.5708" />
    <parent
      link="mani2_link1" />
    <child
      link="mani2_link2" />
    <axis
      xyz="0 0 1" />
    <limit
      lower="-2.35"
      upper="2.35"
      effort="100"
      velocity="0.8" />
  </joint>
  <link
    name="mani2_link3">
    <inertial>
      <origin
        xyz="-0.00018188 -0.11832 0.041393"
        rpy="0 0 0" />
      <mass
        value="0.55009" />
      <inertia
        ixx="0.0009283"
        ixy="-9.2458E-07"
        ixz="-9.3918E-07"
        iyy="0.00082363"
        iyz="1.9373E-05"
        izz="0.00096206" />
    </inertial>
    <visual>
      <origin
        xyz="0 0 0"
        rpy="0 0 0" />
      <geometry>
        <mesh
          filename="package://dualarm_config/meshes/mani2_link3.STL" />
      </geometry>
      <material
        name="">
        <color
          rgba="0.79216 0.81961 0.93333 1" />
      </material>
    </visual>
    <collision>
      <origin
        xyz="0 0 0"
        rpy="0 0 0" />
      <geometry>
        <mesh
          filename="package://dualarm_config/meshes/mani2_link3.STL" />
      </geometry>
    </collision>
  </link>
  <joint
    name="mani2_joint2"
    type="revolute">
    <origin
      xyz="0 -0.069 0.0675"
      rpy="-1.5708 0 0" />
    <parent
      link="mani2_link2" />
    <child
      link="mani2_link3" />
    <axis
      xyz="0 0 1" />
    <limit
      lower="-1.9"
      upper="1.9"
      effort="100"
      velocity="0.8" />
  </joint>
  <link
    name="mani2_link4">
    <inertial>
      <origin
        xyz="-8.8281E-05 -0.009886 0.069843"
        rpy="0 0 0" />
      <mass
        value="0.45928" />
      <inertia
        ixx="0.00040071"
        ixy="-2.3353E-07"
        ixz="-1.992E-06"
        iyy="0.00052253"
        iyz="2.47E-05"
        izz="0.00038096" />
    </inertial>
    <visual>
      <origin
        xyz="0 0 0"
        rpy="0 0 0" />
      <geometry>
        <mesh
          filename="package://dualarm_config/meshes/mani2_link4.STL" />
      </geometry>
      <material
        name="">
        <color
          rgba="0.79216 0.81961 0.93333 1" />
      </material>
    </visual>
    <collision>
      <origin
        xyz="0 0 0"
        rpy="0 0 0" />
      <geometry>
        <mesh
          filename="package://dualarm_config/meshes/mani2_link4.STL" />
      </geometry>
    </collision>
  </link>
  <joint
    name="mani2_joint3"
    type="revolute">
    <origin
      xyz="0 -0.2197 0.069"
      rpy="1.5708 0 0" />
    <parent
      link="mani2_link3" />
    <child
      link="mani2_link4" />
    <axis
      xyz="0 0 1" />
    <limit
      lower="-2.5"
      upper="2.5"
      effort="100"
      velocity="0.8" />
  </joint>
  <link
    name="mani2_link5">
    <inertial>
      <origin
        xyz="0.00019482 -0.11792 0.037427"
        rpy="0 0 0" />
      <mass
        value="0.43981" />
      <inertia
        ixx="0.00052212"
        ixy="1.2216E-07"
        ixz="-9.6251E-08"
        iyy="0.00035826"
        iyz="1.9152E-05"
        izz="0.00054597" />
    </inertial>
    <visual>
      <origin
        xyz="0 0 0"
        rpy="0 0 0" />
      <geometry>
        <mesh
          filename="package://dualarm_config/meshes/mani2_link5.STL" />
      </geometry>
      <material
        name="">
        <color
          rgba="0.79216 0.81961 0.93333 1" />
      </material>
    </visual>
    <collision>
      <origin
        xyz="0 0 0"
        rpy="0 0 0" />
      <geometry>
        <mesh
          filename="package://dualarm_config/meshes/mani2_link5.STL" />
      </geometry>
    </collision>
  </link>
  <joint
    name="mani2_joint4"
    type="revolute">
    <origin
      xyz="0 -0.061 0.0753"
      rpy="-1.5708 0 0" />
    <parent
      link="mani2_link4" />
    <child
      link="mani2_link5" />
    <axis
      xyz="0 0 1" />
    <limit
      lower="-1.8"
      upper="1.8"
      effort="100"
      velocity="0.8" />
  </joint>
  <link
    name="mani2_link6">
    <inertial>
      <origin
        xyz="1.0745E-05 0.030079 0.16626"
        rpy="0 0 0" />
      <mass
        value="0.30699" />
      <inertia
        ixx="0.0004714"
        ixy="3.3142E-08"
        ixz="-6.2237E-09"
        iyy="0.00049632"
        iyz="-4.3014E-05"
        izz="0.00023077" />
    </inertial>
    <visual>
      <origin
        xyz="0 0 0"
        rpy="0 0 0" />
      <geometry>
        <mesh
          filename="package://dualarm_config/meshes/mani2_link6.STL" />
      </geometry>
      <material
        name="">
        <color
          rgba="0.79216 0.81961 0.93333 1" />
      </material>
    </visual>
    <collision>
      <origin
        xyz="0 0 0"
        rpy="0 0 0" />
      <geometry>
        <mesh
          filename="package://dualarm_config/meshes/mani2_link6.STL" />
      </geometry>
    </collision>
  </link>
  <joint
    name="mani2_joint5"
    type="revolute">
    <origin
      xyz="0 -0.2 0.061"
      rpy="-1.5708 0 3.1416" />
    <parent
      link="mani2_link5" />
    <child
      link="mani2_link6" />
    <axis
      xyz="0 0 1" />
    <limit
      lower="-2.15"
      upper="2.15"
      effort="100"
      velocity="0.8" />
  </joint>
  <link
    name="mani2_link7">
    <inertial>
      <origin
        xyz="-0.00010944 -0.0075746 -0.032739"
        rpy="0 0 0" />
      <mass
        value="0.10158" />
      <inertia
        ixx="6.5446E-05"
        ixy="-2.9093E-08"
        ixz="4.8842E-08"
        iyy="6.9978E-05"
        iyz="2.982E-07"
        izz="6.75E-05" />
    </inertial>
    <visual>
      <origin
        xyz="0 0 0"
        rpy="0 0 0" />
      <geometry>
        <mesh
          filename="package://dualarm_config/meshes/mani2_link7.STL" />
      </geometry>
      <material
        name="">
        <color
          rgba="0.79216 0.81961 0.93333 1" />
      </material>
    </visual>
    <collision>
      <origin
        xyz="0 0 0"
        rpy="0 0 0" />
      <geometry>
        <mesh
          filename="package://dualarm_config/meshes/mani2_link7.STL" />
      </geometry>
    </collision>
  </link>
  <joint
    name="mani2_joint6"
    type="revolute">
    <origin
      xyz="0 0.032 0.25"
      rpy="-1.5708 0 0" />
    <parent
      link="mani2_link6" />
    <child
      link="mani2_link7" />
    <axis
      xyz="0 0 -1" />
    <limit
      lower="-2.09"
      upper="2.09"
      effort="100"
      velocity="0.8" />
  </joint>
  <link
    name="mani2_link8">
    <inertial>
      <origin
        xyz="0.00052359 -0.00015741 0.046995"
        rpy="0 0 0" />
      <mass
        value="0.26908" />
      <inertia
        ixx="8.5289E-05"
        ixy="9.3888E-10"
        ixz="-1.0334E-07"
        iyy="0.00013205"
        iyz="-3.8971E-07"
        izz="0.00014078" />
    </inertial>
    <visual>
      <origin
        xyz="0 0 0"
        rpy="0 0 0" />
      <geometry>
        <mesh
          filename="package://dualarm_config/meshes/mani2_eef.STL" />
      </geometry>
      <material
        name="">
        <color
          rgba="0.79216 0.81961 0.93333 1" />
      </material>
    </visual>
    <collision>
      <origin
        xyz="0 0 0"
        rpy="0 0 0" />
      <geometry>
        <mesh
          filename="package://dualarm_config/meshes/mani2_eef.STL" />
      </geometry>
    </collision>
  </link>
  <joint
    name="mani2_joint7"
    type="revolute">
    <origin
      xyz="0 -0.0405 -0.032"
      rpy="1.5708 0 0" />
    <parent
      link="mani2_link7" />
    <child
      link="mani2_link8" />
    <axis
      xyz="0 0 1" />
    <limit
      lower="-2.95"
      upper="2.95"
      effort="100"
      velocity="0.8" />
  </joint>


  <transmission name="right_tran1">
    <type>transmission_interface/SimpleTransmission</type>
    <joint name="mani2_joint1">
      <hardwareInterface>hardware_interface/PositionJointInterface</hardwareInterface>
    </joint>
    <actuator name="right_motor1">
      <hardwareInterface>hardware_interface/PositionJointInterface</hardwareInterface>
      <mechanicalReduction>1</mechanicalReduction>
    </actuator>
  </transmission>
  <transmission name="right_tran2">
    <type>transmission_interface/SimpleTransmission</type>
    <joint name="mani2_joint2">
      <hardwareInterface>hardware_interface/PositionJointInterface</hardwareInterface>
    </joint>
    <actuator name="right_motor2">
      <hardwareInterface>hardware_interface/PositionJointInterface</hardwareInterface>
      <mechanicalReduction>1</mechanicalReduction>
    </actuator>
  </transmission>
  <transmission name="right_tran3">
    <type>transmission_interface/SimpleTransmission</type>
    <joint name="mani2_joint3">
      <hardwareInterface>hardware_interface/PositionJointInterface</hardwareInterface>
    </joint>
    <actuator name="right_motor3">
      <hardwareInterface>hardware_interface/PositionJointInterface</hardwareInterface>
      <mechanicalReduction>1</mechanicalReduction>
    </actuator>
  </transmission>
  <transmission name="right_tran4">
    <type>transmission_interface/SimpleTransmission</type>
    <joint name="mani2_joint4">
      <hardwareInterface>hardware_interface/PositionJointInterface</hardwareInterface>
    </joint>
    <actuator name="right_motor4">
      <hardwareInterface>hardware_interface/PositionJointInterface</hardwareInterface>
      <mechanicalReduction>1</mechanicalReduction>
    </actuator>
  </transmission>
  <transmission name="right_tran5">
    <type>transmission_interface/SimpleTransmission</type>
    <joint name="mani2_joint5">
      <hardwareInterface>hardware_interface/PositionJointInterface</hardwareInterface>
    </joint>
    <actuator name="right_motor5">
      <hardwareInterface>hardware_interface/PositionJointInterface</hardwareInterface>
      <mechanicalReduction>1</mechanicalReduction>
    </actuator>
  </transmission>
  <transmission name="right_tran6">
    <type>transmission_interface/SimpleTransmission</type>
    <joint name="mani2_joint6">
      <hardwareInterface>hardware_interface/PositionJointInterface</hardwareInterface>
    </joint>
    <actuator name="right_motor6">
      <hardwareInterface>hardware_interface/PositionJointInterface</hardwareInterface>
      <mechanicalReduction>1</mechanicalReduction>
    </actuator>
  </transmission>
  <transmission name="right_tran7">
    <type>transmission_interface/SimpleTransmission</type>
    <joint name="mani2_joint7">
      <hardwareInterface>hardware_interface/PositionJointInterface</hardwareInterface>
    </joint>
    <actuator name="right_motor7">
      <hardwareInterface>hardware_interface/PositionJointInterface</hardwareInterface>
      <mechanicalReduction>1</mechanicalReduction>
    </actuator>
  </transmission>

</robot>