<robot name="dualarm">


  <link
    name="mani1_base">
    <inertial>
      <origin
        xyz="0.000214133185221511 -0.000263993773760912 -0.00611775454032076"
        rpy="0 0 0" />
      <mass
        value="3.57330907434109" />
      <inertia
        ixx="0.0125043470138794"
        ixy="4.69689009859497E-05"
        ixz="-9.0888380429557E-06"
        iyy="0.0124805069140377"
        iyz="1.10392895970441E-05"
        izz="0.0248975799456784" />
    </inertial>
    <visual>
      <origin
        xyz="0 0 0"
        rpy="0 0 0" />
      <geometry>
        <mesh
          filename="package://dualarm_config/meshes/mani1_base.STL" />
      </geometry>
      <material
        name="">
        <color
          rgba="0.647058823529412 0.619607843137255 0.588235294117647 1" />
      </material>
    </visual>
    <collision>
      <origin
        xyz="0 0 0"
        rpy="0 0 0" />
      <geometry>
        <mesh
          filename="package://dualarm_config/meshes/mani1_base.STL" />
      </geometry>
    </collision>
  </link>

  <gazebo reference="mani1_base">
              
    		<material>Gazebo/White</material>
  </gazebo>

  <link
    name="mani1_link1">
    <inertial>
      <origin
        xyz="-3.51872665886486E-06 -0.000870878275491564 -0.00474601269745995"
        rpy="0 0 0" />
      <mass
        value="0.446330780520445" />
      <inertia
        ixx="0.000441978892899946"
        ixy="9.59086613795905E-08"
        ixz="6.49516463430428E-08"
        iyy="0.000420405291605374"
        iyz="-5.37864589703489E-06"
        izz="0.000462095403932586" />
    </inertial>
    <visual>
      <origin
        xyz="0 0 0"
        rpy="0 0 0" />
      <geometry>
        <mesh
          filename="package://dualarm_config/meshes/mani1_link1.STL" />
      </geometry>
      <material
        name="">
        <color
          rgba="0.792156862745098 0.819607843137255 0.933333333333333 1" />
      </material>
    </visual>
    <collision>
      <origin
        xyz="0 0 0"
        rpy="0 0 0" />
      <geometry>
        <mesh
          filename="package://dualarm_config/meshes/mani1_link1.STL" />
      </geometry>
    </collision>
  </link>

  <gazebo reference="mani1_link1">
              
    		<material>Gazebo/White</material>
  </gazebo>


  <joint
    name="mani1_fixed"
    type="fixed">
    <origin
      xyz="0 0 0"
      rpy="0 0 0" />
    <parent
      link="mani1_base" />
    <child
      link="mani1_link1" />
    <axis
      xyz="0 0 0" />
  </joint>



  <link
    name="mani1_link2">
    <inertial>
      <origin
        xyz="-6.49524381623627E-07 -0.0106338062219783 0.0790468559653485"
        rpy="0 0 0" />
      <mass
        value="2.1394698564504" />
      <inertia
        ixx="0.00933388216670083"
        ixy="-8.3479236244943E-07"
        ixz="6.3330829985724E-07"
        iyy="0.0116887123268387"
        iyz="0.000853478442579413"
        izz="0.0054725576811765" />
    </inertial>
    <visual>
      <origin
        xyz="0 0 0"
        rpy="0 0 0" />
      <geometry>
        <mesh
          filename="package://dualarm_config/meshes/mani1_link2.STL" />
      </geometry>
      <material
        name="">
        <color
          rgba="0.752941176470588 0.752941176470588 0.752941176470588 1" />
      </material>
    </visual>
    <collision>
      <origin
        xyz="0 0 0"
        rpy="0 0 0" />
      <geometry>
        <mesh
          filename="package://dualarm_config/meshes/mani1_link2.STL" />
      </geometry>
    </collision>
  </link>

  <gazebo reference="mani1_link2">
              
    		<material>Gazebo/White</material>
  </gazebo>

  <joint
    name="mani1_joint1"
    type="revolute">
    <origin
      xyz="0 0 0.022"
      rpy="0 0 0" />
    <parent
      link="mani1_link1" />
    <child
      link="mani1_link2" />
    <axis
      xyz="0 0 1" />
    <limit
      lower="-2.74"
      upper="2.74"
      effort="100"
      velocity="0.8" />
  </joint>

  <link
    name="mani1_link3">
    <inertial>
      <origin
        xyz="9.97578023689037E-06 -0.096396260738586 0.0145605378238661"
        rpy="0 0 0" />
      <mass
        value="1.82427493800269" />
      <inertia
        ixx="0.0123597154706515"
        ixy="1.45225672257562E-06"
        ixz="2.66098831293768E-07"
        iyy="0.00465884584470388"
        iyz="-0.0016099441739936"
        izz="0.0145981943825196" />
    </inertial>
    <visual>
      <origin
        xyz="0 0 0"
        rpy="0 0 0" />
      <geometry>
        <mesh
          filename="package://dualarm_config/meshes/mani1_link3.STL" />
      </geometry>
      <material
        name="">
        <color
          rgba="0.752941176470588 0.752941176470588 0.752941176470588 1" />
      </material>
    </visual>
    <collision>
      <origin
        xyz="0 0 0"
        rpy="0 0 0" />
      <geometry>
        <mesh
          filename="package://dualarm_config/meshes/mani1_link3.STL" />
      </geometry>
    </collision>
  </link>

  <gazebo reference="mani1_link3">
              
    		<material>Gazebo/White</material>
  </gazebo>

  <joint
    name="mani1_joint2"
    type="revolute">
    <origin
      xyz="0 0 0.133"
      rpy="-1.5708 1.0018E-33 -4.3239E-18" />
    <parent
      link="mani1_link2" />
    <child
      link="mani1_link3" />
    <axis
      xyz="0 0 -1" />
    <limit
      lower="-1.52"
      upper="1.52"
      effort="100"
      velocity="0.8" />
  </joint>

  <link
    name="mani1_link4">
    <inertial>
      <origin
        xyz="4.21635561466764E-07 -0.0119138976140091 0.0741259416420922"
        rpy="0 0 0" />
      <mass
        value="1.11094972876502" />
      <inertia
        ixx="0.00436016088344537"
        ixy="-2.3494039962872E-07"
        ixz="-2.01710559005772E-07"
        iyy="0.00465457365898766"
        iyz="0.000583991655089597"
        izz="0.00171072297566677" />
    </inertial>
    <visual>
      <origin
        xyz="0 0 0"
        rpy="0 0 0" />
      <geometry>
        <mesh
          filename="package://dualarm_config/meshes/mani1_link4.STL" />
      </geometry>
      <material
        name="">
        <color
          rgba="0.752941176470588 0.752941176470588 0.752941176470588 1" />
      </material>
    </visual>
    <collision>
      <origin
        xyz="0 0 0"
        rpy="0 0 0" />
      <geometry>
        <mesh
          filename="package://dualarm_config/meshes/mani1_link4.STL" />
      </geometry>
    </collision>
  </link>

  <gazebo reference="mani1_link4">
              
    		<material>Gazebo/White</material>
  </gazebo>

  <joint
    name="mani1_joint3"
    type="revolute">
    <origin
      xyz="0 -0.2 0"
      rpy="1.5708 -4.3239E-18 0" />
    <parent
      link="mani1_link3" />
    <child
      link="mani1_link4" />
    <axis
      xyz="0 0 1" />
    <limit
      lower="-1.6"
      upper="1.6"
      effort="100"
      velocity="0.8" />
  </joint>

  <link
    name="mani1_link5">
    <inertial>
      <origin
        xyz="1.5231209961995E-05 -0.0885578081506746 0.0139839867335461"
        rpy="0 0 0" />
      <mass
        value="1.10694723668742" />
      <inertia
        ixx="0.00638512740402005"
        ixy="1.26114775658813E-06"
        ixz="-3.67727740947096E-07"
        iyy="0.00179774595704778"
        iyz="-0.000911685772003026"
        izz="0.00712624030232044" />
    </inertial>
    <visual>
      <origin
        xyz="0 0 0"
        rpy="0 0 0" />
      <geometry>
        <mesh
          filename="package://dualarm_config/meshes/mani1_link5.STL" />
      </geometry>
      <material
        name="">
        <color
          rgba="0.752941176470588 0.752941176470588 0.752941176470588 1" />
      </material>
    </visual>
    <collision>
      <origin
        xyz="0 0 0"
        rpy="0 0 0" />
      <geometry>
        <mesh
          filename="package://dualarm_config/meshes/mani1_link5.STL" />
      </geometry>
    </collision>
  </link>

  <gazebo reference="mani1_link5">
              
    		<material>Gazebo/White</material>
  </gazebo>

  <joint
    name="mani1_joint4"
    type="revolute">
    <origin
      xyz="0 0 0.13"
      rpy="-1.5708 4.3366E-33 -6.2595E-17" />
    <parent
      link="mani1_link4" />
    <child
      link="mani1_link5" />
    <axis
      xyz="0 0 -1" />
    <limit
      lower="-1.78"
      upper="1.78"
      effort="100"
      velocity="0.8" />
  </joint>

  <link
    name="mani1_link6">
    <inertial>
      <origin
        xyz="2.29603452071085E-05 -0.00728511999418746 0.0627583259845416"
        rpy="0 0 0" />
      <mass
        value="0.888624094816857" />
      <inertia
        ixx="0.00300509646393665"
        ixy="1.01694662376443E-06"
        ixz="-8.01641358100054E-07"
        iyy="0.00332210196460049"
        iyz="0.000289757839226491"
        izz="0.00114424445227424" />
    </inertial>
    <visual>
      <origin
        xyz="0 0 0"
        rpy="0 0 0" />
      <geometry>
        <mesh
          filename="package://dualarm_config/meshes/mani1_link6.STL" />
      </geometry>
      <material
        name="">
        <color
          rgba="0.752941176470588 0.752941176470588 0.752941176470588 1" />
      </material>
    </visual>
    <collision>
      <origin
        xyz="0 0 0"
        rpy="0 0 0" />
      <geometry>
        <mesh
          filename="package://dualarm_config/meshes/mani1_link6.STL" />
      </geometry>
    </collision>
  </link>

  <gazebo reference="mani1_link6">
              
    		<material>Gazebo/White</material>
  </gazebo>

  <joint
    name="mani1_joint5"
    type="revolute">
    <origin
      xyz="0 -0.189 0"
      rpy="1.5708 -6.2595E-17 0" />
    <parent
      link="mani1_link5" />
    <child
      link="mani1_link6" />
    <axis
      xyz="0 0 1" />
    <limit
      lower="-2.35"
      upper="2.35"
      effort="100"
      velocity="0.8" />
  </joint>

  <link
    name="mani1_link7">
    <inertial>
      <origin
        xyz="5.23366069636606E-07 -0.0970566798173588 0.0113923272499066"
        rpy="0 0 0" />
      <mass
        value="0.592227093253045" />
      <inertia
        ixx="0.00265106618523082"
        ixy="-1.63647435150486E-08"
        ixz="-7.36265473728024E-07"
        iyy="0.000643177021908098"
        iyz="-0.000273036189954506"
        izz="0.00292912135647666" />
    </inertial>
    <visual>
      <origin
        xyz="0 0 0"
        rpy="0 0 0" />
      <geometry>
        <mesh
          filename="package://dualarm_config/meshes/mani1_link7.STL" />
      </geometry>
      <material
        name="">
        <color
          rgba="0.752941176470588 0.752941176470588 0.752941176470588 1" />
      </material>
    </visual>
    <collision>
      <origin
        xyz="0 0 0"
        rpy="0 0 0" />
      <geometry>
        <mesh
          filename="package://dualarm_config/meshes/mani1_link7.STL" />
      </geometry>
    </collision>
  </link>

  <gazebo reference="mani1_link7">
              
    		<material>Gazebo/White</material>
  </gazebo>

  <joint
    name="mani1_joint6"
    type="revolute">
    <origin
      xyz="0 0 0.125"
      rpy="-1.5708 -2.206E-48 2.6193E-32" />
    <parent
      link="mani1_link6" />
    <child
      link="mani1_link7" />
    <axis
      xyz="0 0 -1" />
    <limit
      lower="-1.78"
      upper="1.78"
      effort="100"
      velocity="0.8" />
  </joint>

  <link
    name="mani1_eff">
    <inertial>
      <origin
        xyz="0.00052359 -0.00015741 0.046995"
        rpy="0 0 0" />
      <mass
        value="0.26908" />
      <inertia
        ixx="8.5289E-05"
        ixy="9.3888E-10"
        ixz="-1.0334E-07"
        iyy="0.00013205"
        iyz="-3.8971E-07"
        izz="0.00014078" />
    </inertial>
    <visual>
      <origin
        xyz="0 0 0"
        rpy="0 0 0" />
      <geometry>
        <mesh
          filename="package://dualarm_config/meshes/mani1_eef.STL" />
      </geometry>
      <material
        name="">
        <color
          rgba="0.79216 0.81961 0.93333 1" />
      </material>
    </visual>
    <collision>
      <origin
        xyz="0 0 0"
        rpy="0 0 0" />
      <geometry>
        <mesh
          filename="package://dualarm_config/meshes/mani1_eef.STL" />
      </geometry>
    </collision>
  </link>

  <gazebo reference="mani1_eff">
    		<material>Gazebo/White</material>
  </gazebo>

  <joint
    name="mani1_joint7"
    type="revolute">
    <origin
      xyz="0 -0.175 0.0"
      rpy="1.5708 0 0" />
    <parent
      link="mani1_link7" />
    <child
      link="mani1_eff" />
    <axis
      xyz="0 0 1" />
    <limit
      lower="-2.61"
      upper="2.61"
      effort="100"
      velocity="0.8" />
  </joint>













<!-- distance between two manipulator is 46cm (=0.46/2 =0.23) -->
<!-- height between base origin to manipulator base is 11.2cm (=0.112) -->

  





<!-- Transmissions for ROS Control -->

  <transmission name="left_tran1">
    <type>transmission_interface/SimpleTransmission</type>
    <joint name="mani1_joint1">
      <hardwareInterface>hardware_interface/PositionJointInterface</hardwareInterface>
    </joint>
    <actuator name="left_motor1">
      <hardwareInterface>hardware_interface/PositionJointInterface</hardwareInterface>
      <mechanicalReduction>1</mechanicalReduction>
    </actuator>
  </transmission>
  <transmission name="left_tran2">
    <type>transmission_interface/SimpleTransmission</type>
    <joint name="mani1_joint2">
      <hardwareInterface>hardware_interface/PositionJointInterface</hardwareInterface>
    </joint>
    <actuator name="left_motor2">
      <hardwareInterface>hardware_interface/PositionJointInterface</hardwareInterface>
      <mechanicalReduction>1</mechanicalReduction>
    </actuator>
  </transmission>
  <transmission name="left_tran3">
    <type>transmission_interface/SimpleTransmission</type>
    <joint name="mani1_joint3">
      <hardwareInterface>hardware_interface/PositionJointInterface</hardwareInterface>
    </joint>
    <actuator name="left_motor3">
      <hardwareInterface>hardware_interface/PositionJointInterface</hardwareInterface>
      <mechanicalReduction>1</mechanicalReduction>
    </actuator>
  </transmission>
  <transmission name="left_tran4">
    <type>transmission_interface/SimpleTransmission</type>
    <joint name="mani1_joint4">
      <hardwareInterface>hardware_interface/PositionJointInterface</hardwareInterface>
    </joint>
    <actuator name="left_motor4">
      <hardwareInterface>hardware_interface/PositionJointInterface</hardwareInterface>
      <mechanicalReduction>1</mechanicalReduction>
    </actuator>
  </transmission>
  <transmission name="left_tran5">
    <type>transmission_interface/SimpleTransmission</type>
    <joint name="mani1_joint5">
      <hardwareInterface>hardware_interface/PositionJointInterface</hardwareInterface>
    </joint>
    <actuator name="left_motor5">
      <hardwareInterface>hardware_interface/PositionJointInterface</hardwareInterface>
      <mechanicalReduction>1</mechanicalReduction>
    </actuator>
  </transmission>
  <transmission name="left_tran6">
    <type>transmission_interface/SimpleTransmission</type>
    <joint name="mani1_joint6">
      <hardwareInterface>hardware_interface/PositionJointInterface</hardwareInterface>
    </joint>
    <actuator name="left_motor6">
      <hardwareInterface>hardware_interface/PositionJointInterface</hardwareInterface>
      <mechanicalReduction>1</mechanicalReduction>
    </actuator>
  </transmission>
  <transmission name="left_tran7">
    <type>transmission_interface/SimpleTransmission</type>
    <joint name="mani1_joint7">
      <hardwareInterface>hardware_interface/PositionJointInterface</hardwareInterface>
    </joint>
    <actuator name="left_motor7">
      <hardwareInterface>hardware_interface/PositionJointInterface</hardwareInterface>
      <mechanicalReduction>1</mechanicalReduction>
    </actuator>
  </transmission>






  
</robot>